<sdf version='1.6'>
  <world name='default'>
    <light name='sun' type='directional'>
      <cast_shadows>1</cast_shadows>
      <pose frame=''>0 0 10 0 -0 0</pose>
      <diffuse>0.8 0.8 0.8 1</diffuse>
      <specular>0.2 0.2 0.2 1</specular>
      <attenuation>
        <range>1000</range>
        <constant>0.9</constant>
        <linear>0.01</linear>
        <quadratic>0.001</quadratic>
      </attenuation>
      <direction>-0.5 0.1 -0.9</direction>
    </light>
    <model name='ground_plane'>
      <static>1</static>
      <link name='link'>
        <collision name='collision'>
          <geometry>
            <plane>
              <normal>0 0 1</normal>
              <size>100 100</size>
            </plane>
          </geometry>
          <surface>
            <contact>
              <collide_bitmask>65535</collide_bitmask>
              <ode/>
            </contact>
            <friction>
              <ode>
                <mu>100</mu>
                <mu2>50</mu2>
              </ode>
              <torsional>
                <ode/>
              </torsional>
            </friction>
            <bounce/>
          </surface>
          <max_contacts>10</max_contacts>
        </collision>
        <visual name='visual'>
          <cast_shadows>0</cast_shadows>
          <geometry>
            <plane>
              <normal>0 0 1</normal>
              <size>100 100</size>
            </plane>
          </geometry>
          <material>
            <script>
              <uri>file://media/materials/scripts/gazebo.material</uri>
              <name>Gazebo/Grey</name>
            </script>
          </material>
        </visual>
        <self_collide>0</self_collide>
        <enable_wind>0</enable_wind>
        <kinematic>0</kinematic>
      </link>
    </model>
    <gravity>0 0 -9.8</gravity>
    <magnetic_field>6e-06 2.3e-05 -4.2e-05</magnetic_field>
    <atmosphere type='adiabatic'/>
    <physics name='default_physics' default='0' type='ode'>
      <max_step_size>0.001</max_step_size>
      <real_time_factor>1</real_time_factor>
      <real_time_update_rate>1000</real_time_update_rate>
    </physics>
    <scene>
      <ambient>0.4 0.4 0.4 1</ambient>
      <background>0.7 0.7 0.7 1</background>
      <shadows>1</shadows>
    </scene>
    <wind/>
    <spherical_coordinates>
      <surface_model>EARTH_WGS84</surface_model>
      <latitude_deg>0</latitude_deg>
      <longitude_deg>0</longitude_deg>
      <elevation>0</elevation>
      <heading_deg>0</heading_deg>
    </spherical_coordinates>
    <model name='p450_aruco'>
      <model name='aruco_16'>
        <link name='link'>
          <inertial>
            <mass>0.0001</mass>
            <inertia>
              <ixx>1.66667e-05</ixx>
              <iyy>1.66667e-05</iyy>
              <izz>1.66667e-05</izz>
              <ixy>0</ixy>
              <ixz>0</ixz>
              <iyz>0</iyz>
            </inertia>
            <pose frame=''>0 0 0.05 0 -0 0</pose>
          </inertial>
          <collision name='collision'>
            <geometry>
              <box>
                <size>0.08 0.08 0.002</size>
              </box>
            </geometry>
            <max_contacts>10</max_contacts>
            <surface>
              <contact>
                <ode/>
              </contact>
              <bounce/>
              <friction>
                <torsional>
                  <ode/>
                </torsional>
                <ode/>
              </friction>
            </surface>
          </collision>
          <visual name='visual'>
            <cast_shadows>0</cast_shadows>
            <geometry>
              <box>
                <size>0.08 0.08 0.002</size>
              </box>
            </geometry>
            <material>
              <script>
                <uri>model://aruco_16/materials/scripts</uri>
                <uri>model://aruco_16/materials/textures</uri>
                <name>aruco_16/Diffuse</name>
              </script>
            </material>
          </visual>
          <self_collide>0</self_collide>
          <enable_wind>0</enable_wind>
          <kinematic>0</kinematic>
        </link>
        <pose frame=''>-0 0 0.041865 0 -0 0</pose>
      </model>
      <model name='p450'>
        <link name='base_link'>
          <pose frame=''>0 0 0 0 -0 0</pose>
          <inertial>
            <pose frame=''>0 0 0 0 -0 0</pose>
            <mass>1.47</mass>
            <inertia>
              <ixx>0.011</ixx>
              <ixy>0</ixy>
              <ixz>0</ixz>
              <iyy>0.015</iyy>
              <iyz>0</iyz>
              <izz>0.021</izz>
            </inertia>
          </inertial>
          <collision name='base_link_inertia_collision'>
            <pose frame=''>0 0 -0.04 0 -0 0</pose>
            <geometry>
              <box>
                <size>0.32 0.32 0.25</size>
              </box>
            </geometry>
            <surface>
              <contact>
                <ode>
                  <min_depth>0.001</min_depth>
                  <max_vel>0</max_vel>
                </ode>
              </contact>
              <friction>
                <ode/>
                <torsional>
                  <ode/>
                </torsional>
              </friction>
              <bounce/>
            </surface>
            <max_contacts>10</max_contacts>
          </collision>
          <visual name='base_link_inertia_visual'>
            <pose frame=''>0 0 0 0 -0 0</pose>
            <geometry>
              <mesh>
                <scale>1 1 1</scale>
                <uri>model://p450/meshes/p450.stl</uri>
              </mesh>
            </geometry>
            <material>
              <script>
                <name>Gazebo/Grey</name>
                <uri>file://media/materials/scripts/gazebo.material</uri>
              </script>
            </material>
          </visual>
          <gravity>1</gravity>
          <velocity_decay/>
          <self_collide>0</self_collide>
          <enable_wind>0</enable_wind>
          <kinematic>0</kinematic>
        </link>
        <link name='imu_link'>
          <pose frame=''>0 0 0 0 -0 0</pose>
          <inertial>
            <pose frame=''>0 0 0 0 -0 0</pose>
            <mass>0.015</mass>
            <inertia>
              <ixx>1e-05</ixx>
              <ixy>0</ixy>
              <ixz>0</ixz>
              <iyy>1e-05</iyy>
              <iyz>0</iyz>
              <izz>1e-05</izz>
            </inertia>
          </inertial>
          <self_collide>0</self_collide>
          <enable_wind>0</enable_wind>
          <kinematic>0</kinematic>
        </link>
        <joint name='imu_joint' type='revolute'>
          <child>imu_link</child>
          <parent>base_link</parent>
          <axis>
            <xyz>1 0 0</xyz>
            <limit>
              <lower>0</lower>
              <upper>0</upper>
              <effort>0</effort>
              <velocity>0</velocity>
            </limit>
            <dynamics>
              <spring_reference>0</spring_reference>
              <spring_stiffness>0</spring_stiffness>
            </dynamics>
            <use_parent_model_frame>1</use_parent_model_frame>
          </axis>
        </joint>
        <link name='rotor_0'>
          <pose frame=''>0.147 -0.145 0.075 0 -0 0</pose>
          <inertial>
            <pose frame=''>0 0 0 0 -0 0</pose>
            <mass>0.005</mass>
            <inertia>
              <ixx>9.75e-07</ixx>
              <ixy>0</ixy>
              <ixz>0</ixz>
              <iyy>0.000273104</iyy>
              <iyz>0</iyz>
              <izz>0.000274004</izz>
            </inertia>
          </inertial>
          <collision name='rotor_0_collision'>
            <pose frame=''>0 0 0 0 -0 0</pose>
            <geometry>
              <cylinder>
                <length>0.005</length>
                <radius>0.128</radius>
              </cylinder>
            </geometry>
            <surface>
              <contact>
                <ode/>
              </contact>
              <friction>
                <ode/>
                <torsional>
                  <ode/>
                </torsional>
              </friction>
              <bounce/>
            </surface>
            <max_contacts>10</max_contacts>
          </collision>
          <visual name='rotor_0_visual'>
            <pose frame=''>0 0 0 0 -0 0</pose>
            <geometry>
              <mesh>
                <scale>1 1 1</scale>
                <uri>model://p450/meshes/p450_ccw.stl</uri>
              </mesh>
            </geometry>
            <material>
              <script>
                <name>Gazebo/FlatBlack</name>
                <uri>file://media/materials/scripts/gazebo.material</uri>
              </script>
            </material>
          </visual>
          <gravity>1</gravity>
          <velocity_decay/>
          <self_collide>0</self_collide>
          <enable_wind>0</enable_wind>
          <kinematic>0</kinematic>
        </link>
        <joint name='rotor_0_joint' type='revolute'>
          <child>rotor_0</child>
          <parent>base_link</parent>
          <axis>
            <xyz>0 0 1</xyz>
            <limit>
              <lower>-1e+16</lower>
              <upper>1e+16</upper>
            </limit>
            <dynamics>
              <spring_reference>0</spring_reference>
              <spring_stiffness>0</spring_stiffness>
            </dynamics>
            <use_parent_model_frame>1</use_parent_model_frame>
          </axis>
        </joint>
        <link name='rotor_1'>
          <pose frame=''>-0.147 0.145 0.075 0 -0 0</pose>
          <inertial>
            <pose frame=''>0 0 0 0 -0 0</pose>
            <mass>0.005</mass>
            <inertia>
              <ixx>9.75e-07</ixx>
              <ixy>0</ixy>
              <ixz>0</ixz>
              <iyy>0.000273104</iyy>
              <iyz>0</iyz>
              <izz>0.000274004</izz>
            </inertia>
          </inertial>
          <collision name='rotor_1_collision'>
            <pose frame=''>0 0 0 0 -0 0</pose>
            <geometry>
              <cylinder>
                <length>0.005</length>
                <radius>0.128</radius>
              </cylinder>
            </geometry>
            <surface>
              <contact>
                <ode/>
              </contact>
              <friction>
                <ode/>
                <torsional>
                  <ode/>
                </torsional>
              </friction>
              <bounce/>
            </surface>
            <max_contacts>10</max_contacts>
          </collision>
          <visual name='rotor_1_visual'>
            <pose frame=''>0 0 0 0 -0 0</pose>
            <geometry>
              <mesh>
                <scale>1 1 1</scale>
                <uri>model://p450/meshes/p450_ccw.stl</uri>
              </mesh>
            </geometry>
            <material>
              <script>
                <name>Gazebo/FlatBlack</name>
                <uri>file://media/materials/scripts/gazebo.material</uri>
              </script>
            </material>
          </visual>
          <gravity>1</gravity>
          <velocity_decay/>
          <self_collide>0</self_collide>
          <enable_wind>0</enable_wind>
          <kinematic>0</kinematic>
        </link>
        <joint name='rotor_1_joint' type='revolute'>
          <child>rotor_1</child>
          <parent>base_link</parent>
          <axis>
            <xyz>0 0 1</xyz>
            <limit>
              <lower>-1e+16</lower>
              <upper>1e+16</upper>
            </limit>
            <dynamics>
              <spring_reference>0</spring_reference>
              <spring_stiffness>0</spring_stiffness>
            </dynamics>
            <use_parent_model_frame>1</use_parent_model_frame>
          </axis>
        </joint>
        <link name='rotor_2'>
          <pose frame=''>0.147 0.145 0.075 0 -0 0</pose>
          <inertial>
            <pose frame=''>0 0 0 0 -0 0</pose>
            <mass>0.005</mass>
            <inertia>
              <ixx>9.75e-07</ixx>
              <ixy>0</ixy>
              <ixz>0</ixz>
              <iyy>0.000273104</iyy>
              <iyz>0</iyz>
              <izz>0.000274004</izz>
            </inertia>
          </inertial>
          <collision name='rotor_2_collision'>
            <pose frame=''>0 0 0 0 -0 0</pose>
            <geometry>
              <cylinder>
                <length>0.005</length>
                <radius>0.128</radius>
              </cylinder>
            </geometry>
            <surface>
              <contact>
                <ode/>
              </contact>
              <friction>
                <ode/>
                <torsional>
                  <ode/>
                </torsional>
              </friction>
              <bounce/>
            </surface>
            <max_contacts>10</max_contacts>
          </collision>
          <visual name='rotor_2_visual'>
            <pose frame=''>0 0 0 0 -0 0</pose>
            <geometry>
              <mesh>
                <scale>1 1 1</scale>
                <uri>model://p450/meshes/p450_cw.stl</uri>
              </mesh>
            </geometry>
            <material>
              <script>
                <name>Gazebo/FlatBlack</name>
                <uri>file://media/materials/scripts/gazebo.material</uri>
              </script>
            </material>
          </visual>
          <gravity>1</gravity>
          <velocity_decay/>
          <self_collide>0</self_collide>
          <enable_wind>0</enable_wind>
          <kinematic>0</kinematic>
        </link>
        <joint name='rotor_2_joint' type='revolute'>
          <child>rotor_2</child>
          <parent>base_link</parent>
          <axis>
            <xyz>0 0 1</xyz>
            <limit>
              <lower>-1e+16</lower>
              <upper>1e+16</upper>
            </limit>
            <dynamics>
              <spring_reference>0</spring_reference>
              <spring_stiffness>0</spring_stiffness>
            </dynamics>
            <use_parent_model_frame>1</use_parent_model_frame>
          </axis>
        </joint>
        <link name='rotor_3'>
          <pose frame=''>-0.147 -0.145 0.075 0 -0 0</pose>
          <inertial>
            <pose frame=''>0 0 0 0 -0 0</pose>
            <mass>0.005</mass>
            <inertia>
              <ixx>9.75e-07</ixx>
              <ixy>0</ixy>
              <ixz>0</ixz>
              <iyy>0.000273104</iyy>
              <iyz>0</iyz>
              <izz>0.000274004</izz>
            </inertia>
          </inertial>
          <collision name='rotor_3_collision'>
            <pose frame=''>0 0 0 0 -0 0</pose>
            <geometry>
              <cylinder>
                <length>0.005</length>
                <radius>0.128</radius>
              </cylinder>
            </geometry>
            <surface>
              <contact>
                <ode/>
              </contact>
              <friction>
                <ode/>
                <torsional>
                  <ode/>
                </torsional>
              </friction>
              <bounce/>
            </surface>
            <max_contacts>10</max_contacts>
          </collision>
          <visual name='rotor_3_visual'>
            <pose frame=''>0 0 0 0 -0 0</pose>
            <geometry>
              <mesh>
                <scale>1 1 1</scale>
                <uri>model://p450/meshes/p450_cw.stl</uri>
              </mesh>
            </geometry>
            <material>
              <script>
                <name>Gazebo/FlatBlack</name>
                <uri>file://media/materials/scripts/gazebo.material</uri>
              </script>
            </material>
          </visual>
          <gravity>1</gravity>
          <velocity_decay/>
          <self_collide>0</self_collide>
          <enable_wind>0</enable_wind>
          <kinematic>0</kinematic>
        </link>
        <joint name='rotor_3_joint' type='revolute'>
          <child>rotor_3</child>
          <parent>base_link</parent>
          <axis>
            <xyz>0 0 1</xyz>
            <limit>
              <lower>-1e+16</lower>
              <upper>1e+16</upper>
            </limit>
            <dynamics>
              <spring_reference>0</spring_reference>
              <spring_stiffness>0</spring_stiffness>
            </dynamics>
            <use_parent_model_frame>1</use_parent_model_frame>
          </axis>
        </joint>
        <link name='gps::link'>
          <pose frame=''>0.1 0 0 0 -0 0</pose>
          <inertial>
            <pose frame=''>0 0 0 0 -0 0</pose>
            <mass>0.015</mass>
            <inertia>
              <ixx>1e-05</ixx>
              <ixy>0</ixy>
              <ixz>0</ixz>
              <iyy>1e-05</iyy>
              <iyz>0</iyz>
              <izz>1e-05</izz>
            </inertia>
          </inertial>
          <visual name='visual'>
            <geometry>
              <cylinder>
                <radius>0.01</radius>
                <length>0.002</length>
              </cylinder>
            </geometry>
            <material>
              <script>
                <name>Gazebo/Black</name>
                <uri>__default__</uri>
              </script>
            </material>
          </visual>
          <sensor name='gps' type='gps'>
            <pose frame=''>0 0 0 0 -0 0</pose>
            <update_rate>5</update_rate>
            <always_on>1</always_on>
            <visualize>0</visualize>
            <plugin name='gps_plugin' filename='libgazebo_gps_plugin.so'>
              <robotNamespace/>
              <gpsNoise>1</gpsNoise>
              <gpsXYRandomWalk>2.0</gpsXYRandomWalk>
              <gpsZRandomWalk>4.0</gpsZRandomWalk>
              <gpsXYNoiseDensity>2.0e-4</gpsXYNoiseDensity>
              <gpsZNoiseDensity>4.0e-4</gpsZNoiseDensity>
              <gpsVXYNoiseDensity>0.2</gpsVXYNoiseDensity>
              <gpsVZNoiseDensity>0.4</gpsVZNoiseDensity>
            </plugin>
            <gps/>
          </sensor>
          <self_collide>0</self_collide>
          <enable_wind>0</enable_wind>
          <kinematic>0</kinematic>
        </link>
        <joint name='gps_joint' type='fixed'>
          <child>gps::link</child>
          <parent>base_link</parent>
        </joint>
        <plugin name='rosbag' filename='libgazebo_multirotor_base_plugin.so'>
          <robotNamespace/>
          <linkName>base_link</linkName>
          <rotorVelocitySlowdownSim>10</rotorVelocitySlowdownSim>
        </plugin>
        <plugin name='front_right_motor_model' filename='libgazebo_motor_model.so'>
          <robotNamespace/>
          <jointName>rotor_0_joint</jointName>
          <linkName>rotor_0</linkName>
          <turningDirection>ccw</turningDirection>
          <timeConstantUp>0.0125</timeConstantUp>
          <timeConstantDown>0.025</timeConstantDown>
          <maxRotVelocity>1500</maxRotVelocity>
          <motorConstant>8.54858e-06</motorConstant>
          <momentConstant>0.06</momentConstant>
          <commandSubTopic>/gazebo/command/motor_speed</commandSubTopic>
          <motorNumber>0</motorNumber>
          <rotorDragCoefficient>0.000806428</rotorDragCoefficient>
          <rollingMomentCoefficient>1e-06</rollingMomentCoefficient>
          <motorSpeedPubTopic>/motor_speed/0</motorSpeedPubTopic>
          <rotorVelocitySlowdownSim>10</rotorVelocitySlowdownSim>
        </plugin>
        <plugin name='back_left_motor_model' filename='libgazebo_motor_model.so'>
          <robotNamespace/>
          <jointName>rotor_1_joint</jointName>
          <linkName>rotor_1</linkName>
          <turningDirection>ccw</turningDirection>
          <timeConstantUp>0.0125</timeConstantUp>
          <timeConstantDown>0.025</timeConstantDown>
          <maxRotVelocity>1500</maxRotVelocity>
          <motorConstant>8.54858e-06</motorConstant>
          <momentConstant>0.06</momentConstant>
          <commandSubTopic>/gazebo/command/motor_speed</commandSubTopic>
          <motorNumber>1</motorNumber>
          <rotorDragCoefficient>0.000806428</rotorDragCoefficient>
          <rollingMomentCoefficient>1e-06</rollingMomentCoefficient>
          <motorSpeedPubTopic>/motor_speed/1</motorSpeedPubTopic>
          <rotorVelocitySlowdownSim>10</rotorVelocitySlowdownSim>
        </plugin>
        <plugin name='front_left_motor_model' filename='libgazebo_motor_model.so'>
          <robotNamespace/>
          <jointName>rotor_2_joint</jointName>
          <linkName>rotor_2</linkName>
          <turningDirection>cw</turningDirection>
          <timeConstantUp>0.0125</timeConstantUp>
          <timeConstantDown>0.025</timeConstantDown>
          <maxRotVelocity>1500</maxRotVelocity>
          <motorConstant>8.54858e-06</motorConstant>
          <momentConstant>0.06</momentConstant>
          <commandSubTopic>/gazebo/command/motor_speed</commandSubTopic>
          <motorNumber>2</motorNumber>
          <rotorDragCoefficient>0.000806428</rotorDragCoefficient>
          <rollingMomentCoefficient>1e-06</rollingMomentCoefficient>
          <motorSpeedPubTopic>/motor_speed/2</motorSpeedPubTopic>
          <rotorVelocitySlowdownSim>10</rotorVelocitySlowdownSim>
        </plugin>
        <plugin name='back_right_motor_model' filename='libgazebo_motor_model.so'>
          <robotNamespace/>
          <jointName>rotor_3_joint</jointName>
          <linkName>rotor_3</linkName>
          <turningDirection>cw</turningDirection>
          <timeConstantUp>0.0125</timeConstantUp>
          <timeConstantDown>0.025</timeConstantDown>
          <maxRotVelocity>1500</maxRotVelocity>
          <motorConstant>8.54858e-06</motorConstant>
          <momentConstant>0.06</momentConstant>
          <commandSubTopic>/gazebo/command/motor_speed</commandSubTopic>
          <motorNumber>3</motorNumber>
          <rotorDragCoefficient>0.000806428</rotorDragCoefficient>
          <rollingMomentCoefficient>1e-06</rollingMomentCoefficient>
          <motorSpeedPubTopic>/motor_speed/3</motorSpeedPubTopic>
          <rotorVelocitySlowdownSim>10</rotorVelocitySlowdownSim>
        </plugin>
        <plugin name='groundtruth_plugin' filename='libgazebo_groundtruth_plugin.so'>
          <robotNamespace/>
        </plugin>
        <plugin name='magnetometer_plugin' filename='libgazebo_magnetometer_plugin.so'>
          <robotNamespace/>
          <pubRate>100</pubRate>
          <noiseDensity>0.0004</noiseDensity>
          <randomWalk>6.4e-06</randomWalk>
          <biasCorrelationTime>600</biasCorrelationTime>
          <magTopic>/mag</magTopic>
        </plugin>
        <plugin name='barometer_plugin' filename='libgazebo_barometer_plugin.so'>
          <robotNamespace/>
          <pubRate>50</pubRate>
          <baroTopic>/baro</baroTopic>
        </plugin>
        <plugin name='mavlink_interface' filename='libgazebo_mavlink_interface.so'>
          <robotNamespace/>
          <imuSubTopic>/imu</imuSubTopic>
          <gpsSubTopic>/gps</gpsSubTopic>
          <magSubTopic>/mag</magSubTopic>
          <baroSubTopic>/baro</baroSubTopic>
          <mavlink_addr>INADDR_ANY</mavlink_addr>
          <mavlink_udp_port>14560</mavlink_udp_port>
          <serialEnabled>0</serialEnabled>
          <serialDevice>/dev/ttyACM0</serialDevice>
          <baudRate>921600</baudRate>
          <qgc_addr>INADDR_ANY</qgc_addr>
          <qgc_udp_port>14550</qgc_udp_port>
          <hil_mode>0</hil_mode>
          <hil_state_level>0</hil_state_level>
          <enable_lockstep>1</enable_lockstep>
          <use_tcp>1</use_tcp>
          <motorSpeedCommandPubTopic>/gazebo/command/motor_speed</motorSpeedCommandPubTopic>
          <control_channels>
            <channel name='rotor1'>
              <input_index>0</input_index>
              <input_offset>0</input_offset>
              <input_scaling>1200</input_scaling>
              <zero_position_disarmed>0</zero_position_disarmed>
              <zero_position_armed>100</zero_position_armed>
              <joint_control_type>velocity</joint_control_type>
            </channel>
            <channel name='rotor2'>
              <input_index>1</input_index>
              <input_offset>0</input_offset>
              <input_scaling>1200</input_scaling>
              <zero_position_disarmed>0</zero_position_disarmed>
              <zero_position_armed>100</zero_position_armed>
              <joint_control_type>velocity</joint_control_type>
            </channel>
            <channel name='rotor3'>
              <input_index>2</input_index>
              <input_offset>0</input_offset>
              <input_scaling>1200</input_scaling>
              <zero_position_disarmed>0</zero_position_disarmed>
              <zero_position_armed>100</zero_position_armed>
              <joint_control_type>velocity</joint_control_type>
            </channel>
            <channel name='rotor4'>
              <input_index>3</input_index>
              <input_offset>0</input_offset>
              <input_scaling>1200</input_scaling>
              <zero_position_disarmed>0</zero_position_disarmed>
              <zero_position_armed>100</zero_position_armed>
              <joint_control_type>velocity</joint_control_type>
            </channel>
          </control_channels>
        </plugin>
        <static>0</static>
        <plugin name='gazebo_imu_plugin' filename='libgazebo_imu_plugin.so'>
          <robotNamespace/>
          <linkName>imu_link</linkName>
          <imuTopic>/imu</imuTopic>
          <gyroscopeNoiseDensity>0.0003394</gyroscopeNoiseDensity>
          <gyroscopeRandomWalk>3.8785e-05</gyroscopeRandomWalk>
          <gyroscopeBiasCorrelationTime>1000.0</gyroscopeBiasCorrelationTime>
          <gyroscopeTurnOnBiasSigma>0.0087</gyroscopeTurnOnBiasSigma>
          <accelerometerNoiseDensity>0.004</accelerometerNoiseDensity>
          <accelerometerRandomWalk>0.006</accelerometerRandomWalk>
          <accelerometerBiasCorrelationTime>300.0</accelerometerBiasCorrelationTime>
          <accelerometerTurnOnBiasSigma>0.196</accelerometerTurnOnBiasSigma>
        </plugin>
        <plugin name='p3d_base_controller' filename='libgazebo_ros_p3d.so'>
          <alwaysOn>1</alwaysOn>
          <updateRate>50.0</updateRate>
          <bodyName>base_link</bodyName>
          <topicName>/prometheus/ground_truth/p300_basic</topicName>
          <gaussianNoise>0.00</gaussianNoise>
          <frameName>world</frameName>
          <xyzOffsets>0 0 0</xyzOffsets>
          <rpyOffsets>0 0 0</rpyOffsets>
          <robotNamespace>/</robotNamespace>
        </plugin>
        <pose frame=''>-0 0 0.072404 0 -0 0</pose>
      </model>
      <joint name='base_link_JOINT_0' type='fixed'>
        <parent>p450::base_link</parent>
        <child>aruco_16::link</child>
        <pose frame=''>0 0 0 0 -0 0</pose>
        <physics>
          <ode>
            <limit>
              <cfm>0</cfm>
              <erp>0.2</erp>
            </limit>
            <suspension>
              <cfm>0</cfm>
              <erp>0.2</erp>
            </suspension>
          </ode>
        </physics>
      </joint>
      <static>0</static>
      <allow_auto_disable>1</allow_auto_disable>
      <pose frame=''>0 0 0.2 0 -0 0</pose>
    </model>
    <state world_name='default'>
      <sim_time>113 154000000</sim_time>
      <real_time>137 686125987</real_time>
      <wall_time>1683260337 549077724</wall_time>
      <iterations>113154</iterations>
      <model name='ground_plane'>
        <pose frame=''>0 0 0 0 -0 0</pose>
        <scale>1 1 1</scale>
        <link name='link'>
          <pose frame=''>0 0 0 0 -0 0</pose>
          <velocity>0 0 0 0 -0 0</velocity>
          <acceleration>0 0 0 0 -0 0</acceleration>
          <wrench>0 0 0 0 -0 0</wrench>
        </link>
      </model>
      <model name='moving_platform'>
        <pose frame=''>2.04349 -0.09701 0.052771 0 2.7e-05 -0.013278</pose>
        <scale>1 1 1</scale>
        <link name='base_link'>
          <pose frame=''>1.98418 0.014329 0.149995 0 2.7e-05 -0.013278</pose>
          <velocity>0 0 0 0 -0 0</velocity>
          <acceleration>0 0 0 0 -0 0</acceleration>
          <wrench>0 0 0 0 -0 0</wrench>
        </link>
        <link name='left_front_wheel'>
          <pose frame=''>2.18854 0.341645 0.099989 -1.5708 2.7e-05 -0.013278</pose>
          <velocity>0 0 0 0 -0 0</velocity>
          <acceleration>0 0 0 0 -0 0</acceleration>
          <wrench>0 0 0 0 -0 0</wrench>
        </link>
        <link name='left_rear_wheel'>
          <pose frame=''>1.78857 0.346956 0.1 -1.5708 2.7e-05 -0.013278</pose>
          <velocity>0 0 0 0 -0 0</velocity>
          <acceleration>0 0 0 0 -0 0</acceleration>
          <wrench>0 0 0 0 -0 0</wrench>
        </link>
        <link name='right_front_wheel'>
          <pose frame=''>2.17977 -0.318297 0.099989 -1.5708 -0.00096 -0.013278</pose>
          <velocity>0 0 0 0 -0 0</velocity>
          <acceleration>0 0 0 0 -0 0</acceleration>
          <wrench>0 0 0 0 -0 0</wrench>
        </link>
        <link name='right_rear_wheel'>
          <pose frame=''>1.77981 -0.312986 0.1 -1.5708 2.7e-05 -0.013278</pose>
          <velocity>0 0 0 0 -0 0</velocity>
          <acceleration>0 0 0 0 -0 0</acceleration>
          <wrench>0 0 0 0 -0 0</wrench>
        </link>
        <model name='camera_0'>
          <pose frame=''>1.98431 0.014324 0.177345 8e-06 -1.56983 -0.013286</pose>
          <scale>1 1 1</scale>
          <link name='link'>
            <pose frame=''>1.98431 0.014324 0.177345 8e-06 -1.56983 -0.013286</pose>
            <velocity>0 0 0 0 -0 0</velocity>
            <acceleration>0 0 0 0 -0 0</acceleration>
            <wrench>0 0 0 0 -0 0</wrench>
          </link>
        </model>
      </model>
      <model name='p450_aruco'>
        <pose frame=''>-2e-06 -0 0.091944 0 -2.1e-05 0</pose>
        <scale>1 1 1</scale>
        <model name='aruco_16'>
          <pose frame=''>-3e-06 -0 0.133809 0 -2.1e-05 0</pose>
          <scale>1 1 1</scale>
          <link name='link'>
            <pose frame=''>-3e-06 -0 0.133809 0 -2.1e-05 0</pose>
            <velocity>-0 -0 -0 0 -0 0</velocity>
            <acceleration>-3.4e-05 -1.3e-05 -8e-06 4.5e-05 -0.000186 0</acceleration>
            <wrench>-0 -0 -0 0 -0 0</wrench>
          </link>
        </model>
        <model name='p450'>
          <pose frame=''>0 0 0.272404 0 -0 0</pose>
          <scale>1 1 1</scale>
          <link name='base_link'>
            <pose frame=''>-3e-06 -0 0.164348 0 -2.1e-05 0</pose>
            <velocity>-0 -0 -0 0 -0 0</velocity>
            <acceleration>0 -2e-05 0 0.000118 -0 0</acceleration>
            <wrench>0 -2.9e-05 0 0 -0 0</wrench>
          </link>
          <link name='gps::link'>
            <pose frame=''>0.099997 -0 0.16435 0 -2.1e-05 0</pose>
            <velocity>-0 -0 0 0 -0 1e-06</velocity>
            <acceleration>0 -0.000261 0 9e-05 -0 0.001054</acceleration>
            <wrench>0 -4e-06 0 0 -0 0</wrench>
          </link>
          <link name='imu_link'>
            <pose frame=''>-3e-06 -0 0.164348 0 -2.1e-05 0</pose>
            <velocity>-0 -0 -0 -0 -0 -0</velocity>
            <acceleration>0 -2.4e-05 0 -0.000254 0 -1e-06</acceleration>
            <wrench>0 -0 0 0 -0 0</wrench>
          </link>
          <link name='rotor_0'>
            <pose frame=''>0.146995 -0.145 0.239351 0 -2.1e-05 0</pose>
            <velocity>-0 -0 0 0 -0 0</velocity>
            <acceleration>-0 -3e-05 -1.5e-05 0.000105 -0 0</acceleration>
            <wrench>-0 -0 -0 0 -0 0</wrench>
          </link>
          <link name='rotor_1'>
            <pose frame=''>-0.147005 0.145 0.239345 0 -2.1e-05 0</pose>
            <velocity>-0 -0 -0 0 -0 0</velocity>
            <acceleration>0 -3e-05 1.5e-05 0.000105 -0 0</acceleration>
            <wrench>0 -0 0 0 -0 0</wrench>
          </link>
          <link name='rotor_2'>
            <pose frame=''>0.146995 0.145 0.239351 0 -2.1e-05 0</pose>
            <velocity>-0 -0 0 0 -0 0</velocity>
            <acceleration>0 -3e-05 1.5e-05 0.000105 -0 0</acceleration>
            <wrench>0 -0 0 0 -0 0</wrench>
          </link>
          <link name='rotor_3'>
            <pose frame=''>-0.147005 -0.145 0.239345 0 -2.1e-05 0</pose>
            <velocity>-0 -0 -0 0 -0 0</velocity>
            <acceleration>-0 -3e-05 -1.5e-05 0.000104 -0 0</acceleration>
            <wrench>-0 -0 -0 0 -0 0</wrench>
          </link>
        </model>
      </model>
      <light name='sun'>
        <pose frame=''>0 0 10 0 -0 0</pose>
      </light>
    </state>
    <model name='moving_platform'>
      <link name='base_link'>
        <inertial>
          <mass>5</mass>
          <inertia>
            <ixx>0.159375</ixx>
            <ixy>0</ixy>
            <ixz>0</ixz>
            <iyy>0.159375</iyy>
            <iyz>0</iyz>
            <izz>0.3</izz>
          </inertia>
          <pose frame=''>0 0 0 0 -0 0</pose>
        </inertial>
        <pose frame=''>-0.06079 0.110542 0.097222 0 -0 0</pose>
        <gravity>1</gravity>
        <self_collide>0</self_collide>
        <kinematic>0</kinematic>
        <enable_wind>0</enable_wind>
        <visual name='visual'>
          <pose frame=''>0 0 0 0 -0 0</pose>
          <geometry>
            <box>
              <size>0.6 0.6 0.15</size>
            </box>
          </geometry>
          <material>
            <lighting>1</lighting>
            <script>
              <uri>file://media/materials/scripts/gazebo.material</uri>
              <name>Gazebo/SkyBlue</name>
            </script>
            <shader type='pixel'>
              <normal_map>__default__</normal_map>
            </shader>
            <ambient>0.3 0.3 0.3 1</ambient>
            <diffuse>0.7 0.7 0.7 1</diffuse>
            <specular>0.01 0.01 0.01 1</specular>
            <emissive>0 0 0 1</emissive>
          </material>
          <transparency>0</transparency>
          <cast_shadows>1</cast_shadows>
        </visual>
        <collision name='collision'>
          <laser_retro>0</laser_retro>
          <max_contacts>10</max_contacts>
          <pose frame=''>0 0 0 0 -0 0</pose>
          <geometry>
            <box>
              <size>0.6 0.6 0.15</size>
            </box>
          </geometry>
          <surface>
            <friction>
              <ode>
                <mu>1</mu>
                <mu2>1</mu2>
                <fdir1>0 0 0</fdir1>
                <slip1>0</slip1>
                <slip2>0</slip2>
              </ode>
              <torsional>
                <coefficient>1</coefficient>
                <patch_radius>0</patch_radius>
                <surface_radius>0</surface_radius>
                <use_patch_radius>1</use_patch_radius>
                <ode>
                  <slip>0</slip>
                </ode>
              </torsional>
            </friction>
            <bounce>
              <restitution_coefficient>0</restitution_coefficient>
              <threshold>1e+06</threshold>
            </bounce>
            <contact>
              <collide_without_contact>0</collide_without_contact>
              <collide_without_contact_bitmask>1</collide_without_contact_bitmask>
              <collide_bitmask>1</collide_bitmask>
              <ode>
                <soft_cfm>0</soft_cfm>
                <soft_erp>0.2</soft_erp>
                <kp>1e+13</kp>
                <kd>1</kd>
                <max_vel>0.01</max_vel>
                <min_depth>0</min_depth>
              </ode>
              <bullet>
                <split_impulse>1</split_impulse>
                <split_impulse_penetration_threshold>-0.01</split_impulse_penetration_threshold>
                <soft_cfm>0</soft_cfm>
                <soft_erp>0.2</soft_erp>
                <kp>1e+13</kp>
                <kd>1</kd>
              </bullet>
            </contact>
          </surface>
        </collision>
      </link>
      <link name='left_front_wheel'>
        <inertial>
          <mass>0.15</mass>
          <inertia>
            <ixx>0.00040625</ixx>
            <ixy>0</ixy>
            <ixz>0</ixz>
            <iyy>0.00040625</iyy>
            <iyz>0</iyz>
            <izz>0.00075</izz>
          </inertia>
          <pose frame=''>0 0 0 0 -0 0</pose>
        </inertial>
        <pose frame=''>0.13921 0.440542 0.047222 -1.5708 -0 -0</pose>
        <gravity>1</gravity>
        <self_collide>0</self_collide>
        <kinematic>0</kinematic>
        <enable_wind>0</enable_wind>
        <visual name='visual'>
          <pose frame=''>0 0 0 0 -0 0</pose>
          <geometry>
            <cylinder>
              <radius>0.1</radius>
              <length>0.05</length>
            </cylinder>
          </geometry>
          <material>
            <lighting>1</lighting>
            <script>
              <uri>file://media/materials/scripts/gazebo.material</uri>
              <name>Gazebo/Grey</name>
            </script>
            <shader type='pixel'>
              <normal_map>__default__</normal_map>
            </shader>
            <ambient>0.3 0.3 0.3 1</ambient>
            <diffuse>0.7 0.7 0.7 1</diffuse>
            <specular>0.01 0.01 0.01 1</specular>
            <emissive>0 0 0 1</emissive>
          </material>
          <transparency>0</transparency>
          <cast_shadows>1</cast_shadows>
        </visual>
        <collision name='collision'>
          <laser_retro>0</laser_retro>
          <max_contacts>10</max_contacts>
          <pose frame=''>0 0 0 0 -0 0</pose>
          <geometry>
            <cylinder>
              <radius>0.1</radius>
              <length>0.05</length>
            </cylinder>
          </geometry>
          <surface>
            <friction>
              <ode>
                <mu>1</mu>
                <mu2>1</mu2>
                <fdir1>0 0 0</fdir1>
                <slip1>0</slip1>
                <slip2>0</slip2>
              </ode>
              <torsional>
                <coefficient>1</coefficient>
                <patch_radius>0</patch_radius>
                <surface_radius>0</surface_radius>
                <use_patch_radius>1</use_patch_radius>
                <ode>
                  <slip>0</slip>
                </ode>
              </torsional>
            </friction>
            <bounce>
              <restitution_coefficient>0</restitution_coefficient>
              <threshold>1e+06</threshold>
            </bounce>
            <contact>
              <collide_without_contact>0</collide_without_contact>
              <collide_without_contact_bitmask>1</collide_without_contact_bitmask>
              <collide_bitmask>1</collide_bitmask>
              <ode>
                <soft_cfm>0</soft_cfm>
                <soft_erp>0.2</soft_erp>
                <kp>1e+13</kp>
                <kd>1</kd>
                <max_vel>0.01</max_vel>
                <min_depth>0</min_depth>
              </ode>
              <bullet>
                <split_impulse>1</split_impulse>
                <split_impulse_penetration_threshold>-0.01</split_impulse_penetration_threshold>
                <soft_cfm>0</soft_cfm>
                <soft_erp>0.2</soft_erp>
                <kp>1e+13</kp>
                <kd>1</kd>
              </bullet>
            </contact>
          </surface>
        </collision>
      </link>
      <link name='left_rear_wheel'>
        <inertial>
          <mass>0.15</mass>
          <inertia>
            <ixx>0.00040625</ixx>
            <ixy>0</ixy>
            <ixz>0</ixz>
            <iyy>0.00040625</iyy>
            <iyz>0</iyz>
            <izz>0.00075</izz>
          </inertia>
          <pose frame=''>0 0 0 0 -0 0</pose>
        </inertial>
        <pose frame=''>-0.26079 0.440542 0.047222 -1.5708 -0 -0</pose>
        <gravity>1</gravity>
        <self_collide>0</self_collide>
        <kinematic>0</kinematic>
        <enable_wind>0</enable_wind>
        <visual name='visual'>
          <pose frame=''>0 0 0 0 -0 0</pose>
          <geometry>
            <cylinder>
              <radius>0.1</radius>
              <length>0.05</length>
            </cylinder>
          </geometry>
          <material>
            <lighting>1</lighting>
            <script>
              <uri>file://media/materials/scripts/gazebo.material</uri>
              <name>Gazebo/Grey</name>
            </script>
            <shader type='pixel'>
              <normal_map>__default__</normal_map>
            </shader>
            <ambient>0.3 0.3 0.3 1</ambient>
            <diffuse>0.7 0.7 0.7 1</diffuse>
            <specular>0.01 0.01 0.01 1</specular>
            <emissive>0 0 0 1</emissive>
          </material>
          <transparency>0</transparency>
          <cast_shadows>1</cast_shadows>
        </visual>
        <collision name='collision'>
          <laser_retro>0</laser_retro>
          <max_contacts>10</max_contacts>
          <pose frame=''>0 0 0 0 -0 0</pose>
          <geometry>
            <cylinder>
              <radius>0.1</radius>
              <length>0.05</length>
            </cylinder>
          </geometry>
          <surface>
            <friction>
              <ode>
                <mu>1</mu>
                <mu2>1</mu2>
                <fdir1>0 0 0</fdir1>
                <slip1>0</slip1>
                <slip2>0</slip2>
              </ode>
              <torsional>
                <coefficient>1</coefficient>
                <patch_radius>0</patch_radius>
                <surface_radius>0</surface_radius>
                <use_patch_radius>1</use_patch_radius>
                <ode>
                  <slip>0</slip>
                </ode>
              </torsional>
            </friction>
            <bounce>
              <restitution_coefficient>0</restitution_coefficient>
              <threshold>1e+06</threshold>
            </bounce>
            <contact>
              <collide_without_contact>0</collide_without_contact>
              <collide_without_contact_bitmask>1</collide_without_contact_bitmask>
              <collide_bitmask>1</collide_bitmask>
              <ode>
                <soft_cfm>0</soft_cfm>
                <soft_erp>0.2</soft_erp>
                <kp>1e+13</kp>
                <kd>1</kd>
                <max_vel>0.01</max_vel>
                <min_depth>0</min_depth>
              </ode>
              <bullet>
                <split_impulse>1</split_impulse>
                <split_impulse_penetration_threshold>-0.01</split_impulse_penetration_threshold>
                <soft_cfm>0</soft_cfm>
                <soft_erp>0.2</soft_erp>
                <kp>1e+13</kp>
                <kd>1</kd>
              </bullet>
            </contact>
          </surface>
        </collision>
      </link>
      <link name='right_front_wheel'>
        <inertial>
          <mass>0.15</mass>
          <inertia>
            <ixx>0.00040625</ixx>
            <ixy>0</ixy>
            <ixz>0</ixz>
            <iyy>0.00040625</iyy>
            <iyz>0</iyz>
            <izz>0.00075</izz>
          </inertia>
          <pose frame=''>0 0 0 0 -0 0</pose>
        </inertial>
        <pose frame=''>0.13921 -0.219458 0.047222 -1.5708 -0.000987 -0</pose>
        <gravity>1</gravity>
        <self_collide>0</self_collide>
        <kinematic>0</kinematic>
        <enable_wind>0</enable_wind>
        <visual name='visual'>
          <pose frame=''>0 0 0 0 -0 0</pose>
          <geometry>
            <cylinder>
              <radius>0.1</radius>
              <length>0.05</length>
            </cylinder>
          </geometry>
          <material>
            <lighting>1</lighting>
            <script>
              <uri>file://media/materials/scripts/gazebo.material</uri>
              <name>Gazebo/Grey</name>
            </script>
            <shader type='pixel'>
              <normal_map>__default__</normal_map>
            </shader>
            <ambient>0.3 0.3 0.3 1</ambient>
            <diffuse>0.7 0.7 0.7 1</diffuse>
            <specular>0.01 0.01 0.01 1</specular>
            <emissive>0 0 0 1</emissive>
          </material>
          <transparency>0</transparency>
          <cast_shadows>1</cast_shadows>
        </visual>
        <collision name='collision'>
          <laser_retro>0</laser_retro>
          <max_contacts>10</max_contacts>
          <pose frame=''>0 0 0 0 -0 0</pose>
          <geometry>
            <cylinder>
              <radius>0.1</radius>
              <length>0.05</length>
            </cylinder>
          </geometry>
          <surface>
            <friction>
              <ode>
                <mu>1</mu>
                <mu2>1</mu2>
                <fdir1>0 0 0</fdir1>
                <slip1>0</slip1>
                <slip2>0</slip2>
              </ode>
              <torsional>
                <coefficient>1</coefficient>
                <patch_radius>0</patch_radius>
                <surface_radius>0</surface_radius>
                <use_patch_radius>1</use_patch_radius>
                <ode>
                  <slip>0</slip>
                </ode>
              </torsional>
            </friction>
            <bounce>
              <restitution_coefficient>0</restitution_coefficient>
              <threshold>1e+06</threshold>
            </bounce>
            <contact>
              <collide_without_contact>0</collide_without_contact>
              <collide_without_contact_bitmask>1</collide_without_contact_bitmask>
              <collide_bitmask>1</collide_bitmask>
              <ode>
                <soft_cfm>0</soft_cfm>
                <soft_erp>0.2</soft_erp>
                <kp>1e+13</kp>
                <kd>1</kd>
                <max_vel>0.01</max_vel>
                <min_depth>0</min_depth>
              </ode>
              <bullet>
                <split_impulse>1</split_impulse>
                <split_impulse_penetration_threshold>-0.01</split_impulse_penetration_threshold>
                <soft_cfm>0</soft_cfm>
                <soft_erp>0.2</soft_erp>
                <kp>1e+13</kp>
                <kd>1</kd>
              </bullet>
            </contact>
          </surface>
        </collision>
      </link>
      <link name='right_rear_wheel'>
        <inertial>
          <mass>0.15</mass>
          <inertia>
            <ixx>0.00040625</ixx>
            <ixy>0</ixy>
            <ixz>0</ixz>
            <iyy>0.00040625</iyy>
            <iyz>0</iyz>
            <izz>0.00075</izz>
          </inertia>
          <pose frame=''>0 0 0 0 -0 0</pose>
        </inertial>
        <pose frame=''>-0.26079 -0.219458 0.047222 -1.5708 -0 -0</pose>
        <gravity>1</gravity>
        <self_collide>0</self_collide>
        <kinematic>0</kinematic>
        <enable_wind>0</enable_wind>
        <visual name='visual'>
          <pose frame=''>0 0 0 0 -0 0</pose>
          <geometry>
            <cylinder>
              <radius>0.1</radius>
              <length>0.05</length>
            </cylinder>
          </geometry>
          <material>
            <lighting>1</lighting>
            <script>
              <uri>file://media/materials/scripts/gazebo.material</uri>
              <name>Gazebo/Grey</name>
            </script>
            <shader type='pixel'>
              <normal_map>__default__</normal_map>
            </shader>
            <ambient>0.3 0.3 0.3 1</ambient>
            <diffuse>0.7 0.7 0.7 1</diffuse>
            <specular>0.01 0.01 0.01 1</specular>
            <emissive>0 0 0 1</emissive>
          </material>
          <transparency>0</transparency>
          <cast_shadows>1</cast_shadows>
        </visual>
        <collision name='collision'>
          <laser_retro>0</laser_retro>
          <max_contacts>10</max_contacts>
          <pose frame=''>0 0 0 0 -0 0</pose>
          <geometry>
            <cylinder>
              <radius>0.1</radius>
              <length>0.05</length>
            </cylinder>
          </geometry>
          <surface>
            <friction>
              <ode>
                <mu>1</mu>
                <mu2>1</mu2>
                <fdir1>0 0 0</fdir1>
                <slip1>0</slip1>
                <slip2>0</slip2>
              </ode>
              <torsional>
                <coefficient>1</coefficient>
                <patch_radius>0</patch_radius>
                <surface_radius>0</surface_radius>
                <use_patch_radius>1</use_patch_radius>
                <ode>
                  <slip>0</slip>
                </ode>
              </torsional>
            </friction>
            <bounce>
              <restitution_coefficient>0</restitution_coefficient>
              <threshold>1e+06</threshold>
            </bounce>
            <contact>
              <collide_without_contact>0</collide_without_contact>
              <collide_without_contact_bitmask>1</collide_without_contact_bitmask>
              <collide_bitmask>1</collide_bitmask>
              <ode>
                <soft_cfm>0</soft_cfm>
                <soft_erp>0.2</soft_erp>
                <kp>1e+13</kp>
                <kd>1</kd>
                <max_vel>0.01</max_vel>
                <min_depth>0</min_depth>
              </ode>
              <bullet>
                <split_impulse>1</split_impulse>
                <split_impulse_penetration_threshold>-0.01</split_impulse_penetration_threshold>
                <soft_cfm>0</soft_cfm>
                <soft_erp>0.2</soft_erp>
                <kp>1e+13</kp>
                <kd>1</kd>
              </bullet>
            </contact>
          </surface>
        </collision>
      </link>
      <model name='camera_0'>
        <pose frame=''>-0.060656 0.110538 0.124572 8e-06 -1.56986 -8e-06</pose>
        <link name='link'>
          <inertial>
            <mass>0.01</mass>
            <inertia>
              <ixx>1.66667e-05</ixx>
              <iyy>1.66667e-05</iyy>
              <izz>1.66667e-05</izz>
              <ixy>0</ixy>
              <ixz>0</ixz>
              <iyz>0</iyz>
            </inertia>
            <pose frame=''>0 0 0 0 -0 0</pose>
          </inertial>
          <collision name='collision'>
            <geometry>
              <box>
                <size>0.1 0.1 0.1</size>
              </box>
            </geometry>
            <max_contacts>10</max_contacts>
            <surface>
              <contact>
                <ode/>
              </contact>
              <bounce/>
              <friction>
                <torsional>
                  <ode/>
                </torsional>
                <ode/>
              </friction>
            </surface>
          </collision>
          <visual name='visual'>
            <geometry>
              <box>
                <size>0.1 0.1 0.1</size>
              </box>
            </geometry>
          </visual>
          <sensor name='camera' type='camera'>
            <camera name='__default__'>
              <horizontal_fov>1.047</horizontal_fov>
              <image>
                <width>640</width>
                <height>480</height>
              </image>
              <clip>
                <near>0.1</near>
                <far>100</far>
              </clip>
            </camera>
            <always_on>1</always_on>
            <update_rate>30</update_rate>
            <visualize>1</visualize>
            <plugin name='camera_plugin' filename='libgazebo_ros_camera.so'>
              <robotNamespace>/moving_platform/sensor</robotNamespace>
              <alwaysOn>1</alwaysOn>
              <imageTopicName>image_raw</imageTopicName>
              <cameraInfoTopicName>camera_info</cameraInfoTopicName>
              <updateRate>30.0</updateRate>
              <cameraName>camera_lookup</cameraName>
              <frameName>/camera_0::link</frameName>
              <hackBaseline>0</hackBaseline>
              <distortionK1>0.0</distortionK1>
              <distortionK2>0.0</distortionK2>
              <distortionK3>0.0</distortionK3>
              <distortionT1>0.0</distortionT1>
              <distortionT2>0.0</distortionT2>
            </plugin>
          </sensor>
          <self_collide>0</self_collide>
          <enable_wind>0</enable_wind>
          <kinematic>0</kinematic>
        </link>
      </model>
      <joint name='camera_joint' type='fixed'>
        <parent>base_link</parent>
        <child>camera_0::link</child>
        <pose frame=''>0 0 0 0 -0 0</pose>
        <physics>
          <ode>
            <limit>
              <cfm>0</cfm>
              <erp>0.2</erp>
            </limit>
            <suspension>
              <cfm>0</cfm>
              <erp>0.2</erp>
            </suspension>
          </ode>
        </physics>
      </joint>
      <joint name='left_front_wheel_joint' type='revolute'>
        <parent>base_link</parent>
        <child>left_front_wheel</child>
        <pose frame=''>0 0 0 0 -0 0</pose>
        <axis>
          <xyz>0 0 1</xyz>
          <use_parent_model_frame>0</use_parent_model_frame>
          <limit>
            <lower>-1.79769e+308</lower>
            <upper>1.79769e+308</upper>
            <effort>-1</effort>
            <velocity>-1</velocity>
          </limit>
          <dynamics>
            <spring_reference>0</spring_reference>
            <spring_stiffness>0</spring_stiffness>
            <damping>0</damping>
            <friction>0</friction>
          </dynamics>
        </axis>
        <physics>
          <ode>
            <limit>
              <cfm>0</cfm>
              <erp>0.2</erp>
            </limit>
            <suspension>
              <cfm>0</cfm>
              <erp>0.2</erp>
            </suspension>
          </ode>
        </physics>
      </joint>
      <joint name='left_rear_wheel_joint' type='revolute'>
        <parent>base_link</parent>
        <child>left_rear_wheel</child>
        <pose frame=''>0 0 0 0 -0 0</pose>
        <axis>
          <xyz>0 0 1</xyz>
          <use_parent_model_frame>0</use_parent_model_frame>
          <limit>
            <lower>-1.79769e+308</lower>
            <upper>1.79769e+308</upper>
            <effort>-1</effort>
            <velocity>-1</velocity>
          </limit>
          <dynamics>
            <spring_reference>0</spring_reference>
            <spring_stiffness>0</spring_stiffness>
            <damping>0</damping>
            <friction>0</friction>
          </dynamics>
        </axis>
        <physics>
          <ode>
            <limit>
              <cfm>0</cfm>
              <erp>0.2</erp>
            </limit>
            <suspension>
              <cfm>0</cfm>
              <erp>0.2</erp>
            </suspension>
          </ode>
        </physics>
      </joint>
      <joint name='right_front_wheel_joint' type='revolute'>
        <parent>base_link</parent>
        <child>right_front_wheel</child>
        <pose frame=''>0 0 0 0 -0 0</pose>
        <axis>
          <xyz>0 0 1</xyz>
          <use_parent_model_frame>0</use_parent_model_frame>
          <limit>
            <lower>-1.79769e+308</lower>
            <upper>1.79769e+308</upper>
            <effort>-1</effort>
            <velocity>-1</velocity>
          </limit>
          <dynamics>
            <spring_reference>0</spring_reference>
            <spring_stiffness>0</spring_stiffness>
            <damping>0</damping>
            <friction>0</friction>
          </dynamics>
        </axis>
        <physics>
          <ode>
            <limit>
              <cfm>0</cfm>
              <erp>0.2</erp>
            </limit>
            <suspension>
              <cfm>0</cfm>
              <erp>0.2</erp>
            </suspension>
          </ode>
        </physics>
      </joint>
      <joint name='right_rear_wheel_joint' type='revolute'>
        <parent>base_link</parent>
        <child>right_rear_wheel</child>
        <pose frame=''>0 0 0 0 -0 0</pose>
        <axis>
          <xyz>0 0 1</xyz>
          <use_parent_model_frame>0</use_parent_model_frame>
          <limit>
            <lower>-1.79769e+308</lower>
            <upper>1.79769e+308</upper>
            <effort>-1</effort>
            <velocity>-1</velocity>
          </limit>
          <dynamics>
            <spring_reference>0</spring_reference>
            <spring_stiffness>0</spring_stiffness>
            <damping>0</damping>
            <friction>0</friction>
          </dynamics>
        </axis>
        <physics>
          <ode>
            <limit>
              <cfm>0</cfm>
              <erp>0.2</erp>
            </limit>
            <suspension>
              <cfm>0</cfm>
              <erp>0.2</erp>
            </suspension>
          </ode>
        </physics>
      </joint>
      <static>0</static>
      <allow_auto_disable>1</allow_auto_disable>
      <pose frame=''>2.04349 -0.09701 0.052771 0 2.7e-05 -0.013278</pose>
    </model>
    <gui fullscreen='0'>
      <camera name='user_camera'>
        <pose frame=''>4.95695 1.41698 4.89473 0 0.925799 -2.90921</pose>
        <view_controller>orbit</view_controller>
        <projection_type>perspective</projection_type>
      </camera>
    </gui>
  </world>
</sdf>
